//: Playground - noun: a place where people can play

import UIKit


//1.表示并抛出错误
//在 Swift 中，错误用符合Error协议的类型的值来表示。这个空协议表明该类型可以用于错误处理。

enum VendingMachineError: Error {
    case invalidSelection                    //选择无效
    case insufficientFunds(coinsNeeded: Int) //金额不足
    case outOfStock                          //缺货
}


//2.处理错误，4种方法

//（1）
//用throwing 函数处理错误
//func canThrowErrors() throws -> String
//func cannotThrowErrors() -> String

struct Item {
    var price: Int
    var count: Int
}

class VendingMachine {
    var inventory = [
        "Candy Bar": Item(price: 12, count: 7),
        "Chips": Item(price: 10, count: 4),
        "Pretzels": Item(price: 7, count: 11)
    ]
    var coinsDeposited = 0
    func dispenseSnack(snack: String) {
        print("Dispensing \(snack)")
    }
    
    func vend(itemNamed name: String) throws {
        guard let item = inventory[name] else {
            throw VendingMachineError.invalidSelection
        }
        
        guard item.count > 0 else {
            throw VendingMachineError.outOfStock
        }
        
        guard item.price <= coinsDeposited else {
            throw VendingMachineError.insufficientFunds(coinsNeeded: item.price - coinsDeposited)
        }
        
        coinsDeposited -= item.price
        
        var newItem = item
        newItem.count -= 1
        inventory[name] = newItem
        
        print("Dispensing \(name)")
    }
}

//因为vend(itemNamed:)方法会传递出它抛出的任何错误，在你的代码中调用此方法的地方，必须要么直接处理这些错误——使用do-catch语句，try?或try!；要么继续将这些错误传递下去。
let favoriteSnacks = [
    "Alice": "Chips",
    "Bob": "Licorice",
    "Eve": "Pretzels",
]
func buyFavoriteSnack(person: String, vendingMachine: VendingMachine) throws {
    let snackName = favoriteSnacks[person] ?? "Candy Bar"
    try vendingMachine.vend(itemNamed: snackName)
}

//throwing构造器能像throwing函数一样传递错误.
//例如下面代码中的PurchasedSnack构造器在构造过程中调用了throwing函数,并且通过传递到它的调用者来处理这些错误。
struct PurchasedSnack {
    let name: String
    init(name: String, vendingMachine: VendingMachine) throws {
        try vendingMachine.vend(itemNamed: name)
        self.name = name
    }
}


//(2)
//用 Do-Catch 处理错误
//do {
//    try expression
//    statements
//} catch pattern 1 {
//    statements
//} catch pattern 2 where condition {
//    statements
//}
var vendingMachine = VendingMachine()
vendingMachine.coinsDeposited = 8
do {
    try buyFavoriteSnack(person: "Alice", vendingMachine: vendingMachine)
} catch VendingMachineError.invalidSelection {
    print("Invalid Selection.")
} catch VendingMachineError.outOfStock {
    print("Out of Stock.")
} catch VendingMachineError.insufficientFunds(let coinsNeeded) {
    print("Insufficient funds. Please insert an additional \(coinsNeeded) coins.")
}


//(3)
//将错误转换成可选值
//可以使用try?通过将错误转换成一个可选值来处理错误。如果在评估try?表达式时一个错误被抛出，那么表达式的值就是nil。
func someThrowingFunction() throws -> Int {
    return 2>1 ? 2: 1
}

let x = try? someThrowingFunction()

let y: Int?
do {
    y = try someThrowingFunction()
} catch {
    y = nil
}

//（4）
//禁用错误传递
//有时你知道某个throwing函数实际上在运行时是不会抛出错误的，在这种情况下，你可以在表达式前面写try!来禁用错误传递，这会把调用包装在一个不会有错误抛出的运行时断言中。如果真的抛出了错误，你会得到一个运行时错误。
let photo = try! FileManager.default.contentsOfDirectory(atPath: "")


//3指定清理操作
//可以使用defer语句在即将离开当前代码块时执行一系列语句。该语句让你能执行一些必要的清理工作，不管是以何种方式离开当前代码块的——无论是由于抛出错误而离开，还是由于诸如return或者break的语句。例如，你可以用defer语句来确保文件描述符得以关闭，以及手动分配的内存得以释放。
//
//defer语句将代码的执行延迟到当前的作用域退出之前。该语句由defer关键字和要被延迟执行的语句组成。延迟执行的语句不能包含任何控制转移语句，例如break或是return语句，或是抛出一个错误。延迟执行的操作会按照它们被指定时的顺序的相反顺序执行——也就是说，第一条defer语句中的代码会在第二条defer语句中的代码被执行之后才执行，以此类推。
//func processFile(filename: String) throws {
//    if exists(filename) {
//        let file = open(filename)
//        defer {
//            close(file)
//        }
//        while let line = try file.readline() {
//            // 处理文件。
//        }
//        // close(file) 会在这里被调用，即作用域的最后。
//    }
//}
